Workbook

Sheet Anleitung
A1: FRESCA-PROJEKT — KALKULATION EIGENE GRAPEFRUIT-LIMONADE
A3: WOZU DIESE MAPPE
B4: Sie rechnet durch, was dein Getränk kostet, was du daran verdienst und ab wann sich die erste Charge trägt. Alles hängt zusammen: Änderst du eine Annahme, rechnet sich die ganze Mappe neu.
A6: SO ARBEITEST DU DAMIT
A7: Schritt 1 | B7: Öffne das Blatt 'Annahmen'. NUR dort trägst du etwas ein — alle gelben Felder.
A8: Schritt 2 | B8: Ersetze die Startwerte durch das, was in den echten Angeboten von Abfüller und Aromahaus steht. Die Startwerte sind belastbare Marktschätzungen — aber eben Schätzungen.
A9: Schritt 3 | B9: Auf 'Rezepturvarianten' stellst du Zucker, Süßstoff und Saftanteil je Variante ein.
A10: Schritt 4 | B10: Alle anderen Blätter rechnen automatisch. Dort bitte nichts überschreiben.
A12: FARBLEGENDE
A13: Gelb hinterlegt | B13: Dein Eingabefeld. Nur diese Zellen ändern.
A14: Blaue Schrift | B14: Fest eingetragener Wert — eine Annahme oder eine Zahl aus einem Angebot.
A15: Schwarze Schrift | B15: Berechnet. Nicht überschreiben.
A16: Grüne Schrift | B16: Verweis auf ein anderes Blatt dieser Mappe.
A18: DIE BLÄTTER
A19: Annahmen | B19: Alle Eingaben: Stückkosten, Rohstoffpreise, Einmalkosten, Fixkosten, Verkaufspreise.
A20: Rezepturvarianten | B20: A = Vollzucker · B = Fresca-Original (Hybrid) · C = nur Zucker, reduziert · D = wie C, aber 6 % Saft.
A21: Stückkosten | B21: Was eine Dose kostet — je Variante und je Chargengröße.
A22: Marge & Preiskette | B22: Was du je Absatzkanal verdienst (Online, Gastro, Fachhandel, LEH).
A23: Break-even | B23: Ab wie vielen verkauften Dosen die erste Charge im Plus ist.
A24: Jahresszenarien | B24: Vom Nebenerwerb bis zum Hauptberuf — was welcher Absatz bedeutet.
A25: Verkostung | B25: Auswertung der Blindverkostung. Trag die Papierbögen hier ein.
A27: WICHTIG
B28: Die Startwerte stammen aus Marktrecherche, nicht aus Angeboten. Deine erste Aufgabe ist, sie durch echte Zahlen zu ersetzen. Bis dahin ist jedes Ergebnis hier eine Indikation — keine Entscheidungsgrundlage.

Sheet Annahmen
A1: ANNAHMEN — nur die gelben Felder ändern
A3: 1. PROJEKT-GRUNDDATEN
A4: Chargengröße (Dosen) | B4: 20000
A5: Gebindegröße (ml) | B5: 330
A6: Gewählte Rezepturvariante (A / B / C / D) | B6: B | F6: Steuert die Blätter 'Marge & Preiskette', 'Break-even' und 'Jahresszenarien'.
A8: 2. STÜCKKOSTEN NACH CHARGENGRÖSSE (€ je Dose) — aus den Abfüller-Angeboten eintragen
A9: Kostenposition | B9: 20000 | C9: 50000 | D9: 100000
A10: Leerdose + Deckel | B10: 0.15 | C10: 0.135 | D10: 0.12 | F10: Genau diese sechs Zeilen beim Abfüller anfragen — dann sind Angebote vergleichbar.
A11: Sleeve (Druck + Aufbringen) | B11: 0.05 | C11: 0.04 | D11: 0.03
A12: Abfüllung (Lohnkosten) | B12: 0.12 | C12: 0.09 | D12: 0.07
A13: Sekundärverpackung (Tray, Karton, Palette) | B13: 0.03 | C13: 0.025 | D13: 0.02
A14: Basis-Rohstoffe (Wasser, CO2, Säure, Konservierung) | B14: 0.02 | C14: 0.018 | D14: 0.016
A15: Aroma / Konzentrat | B15: 0.025 | C15: 0.022 | D15: 0.02
A17: 3. REZEPTURABHÄNGIGE ROHSTOFFPREISE
A18: Zucker (€ je kg) | B18: 0.7 | F18: EU-Weißzucker im Großhandel. Schwankt stark — aktuellen Preis erfragen.
A19: Grapefruitsaft aus Konzentrat (€ je Liter Fertigsaft) | B19: 1.6
A20: Süßstoff-Blend Sucralose + Acesulfam-K (€ je Dose) | B20: 0.01
A22: 4. ZUSCHLÄGE JE DOSE (€)
A23: EWP Pfand-Systembeitrag (Produzentenbeitrag) | B23: 0.02 | F23: Tarif bei EWP Recycling Pfand Österreich erfragen. NICHT das 25-Cent-Pfand selbst — das ist ein durchlaufender Posten.
A24: Fracht Abfüller → eigenes Lager | B24: 0.02
A26: 5. EINMALKOSTEN (€) — fallen nur einmal vor der ersten Charge an
A27: Rezepturentwicklung Aromahaus | B27: 3500
A28: Nährwert- & Stabilitätsanalyse (Labor) | B28: 600
A29: Dosendesign / Grafik | B29: 1500
A30: Markenanmeldung EUIPO (1 Klasse, Kl. 32) | B30: 850
A31: Gewerbeanmeldung, LMU-Registrierung, HACCP-Konzept | B31: 650
A32: EWP- und ARA-Registrierung (Setup) | B32: 350
A33: Summe Einmalkosten | B33: =SUM(B27:B32) -> 7450
A35: 6. FIXKOSTEN JAHR 1 (€)
A36: Lagermiete | B36: 1200
A37: Logistik / Versand | B37: 1500
A38: Marketing, Muster, Messen | B38: 2500
A39: Buchhaltung, Versicherung, Sonstiges | B39: 800
A40: Summe Fixkosten Jahr 1 | B40: =SUM(B36:B39) -> 6000
A42: 7. ABSATZKANÄLE — Nettopreise, ohne 20 % USt und ohne Pfand
A43: Kanal | B43: Abgabepreis netto (€/Dose) | C43: Anteil am Absatz
A44: Online-Direktverkauf | B44: 2.2 | C44: 0.25
A45: Gastronomie | B45: 1 | C45: 0.6
A46: Feinkost / Getränkefachhandel | B46: 0.85 | C46: 0.15
A47: LEH / Großhandel | B47: 0.72 | C47: 0
...

Sheet Rezepturvarianten
A1: REZEPTURVARIANTEN — Zucker, Süßstoff, Saftanteil
A3: Parameter | B3: A | C3: B | D3: C | E3: D
A4: Bezeichnung | B4: Vollzucker | C4: Fresca-Original (Hybrid) | D4: Nur Zucker, reduziert | E4: Nur Zucker + 6 % Saft
A6: EINGABEN
A7: Zucker (g je 100 ml) | B7: 10 | C7: 6 | D7: 6 | E7: 6 | G7: Das Costa-Rica-Original liegt bei ca. 5,9 g/100 ml — Coca-Cola bei ca. 10,6 g.
A8: Süßstoff enthalten (1 = ja, 0 = nein) | B8: 0 | C8: 1 | D8: 0 | E8: 0
A9: Grapefruitsaft-Anteil | B9: 0.01 | C9: 0.01 | D9: 0.01 | E9: 0.06 | G9: Ob 'Fruchtlimonade' auf die Dose darf, hängt vom Mindestfruchtgehalt ab — Österr. Lebensmittelbuch Kap. B26, prüfen lassen.
A11: BERECHNETE REZEPTURKOSTEN (€ je Dose)
A12: Zucker je Dose (g) | B12: =B7*Annahmen!$B$5/100 -> 33 | C12: =C7*Annahmen!$B$5/100 -> 19.8 | D12: =D7*Annahmen!$B$5/100 -> 19.8 | E12: =E7*Annahmen!$B$5/100 -> 19.8
A13: Zuckerkosten | B13: =B12/1000*Annahmen!$B$18 -> 0.0231 | C13: =C12/1000*Annahmen!$B$18 -> 0.01386 | D13: =D12/1000*Annahmen!$B$18 -> 0.01386 | E13: =E12/1000*Annahmen!$B$18 -> 0.01386
A14: Saftmenge je Dose (ml) | B14: =Annahmen!$B$5*B9 -> 3.3 | C14: =Annahmen!$B$5*C9 -> 3.3 | D14: =Annahmen!$B$5*D9 -> 3.3 | E14: =Annahmen!$B$5*E9 -> 19.8
A15: Saftkosten | B15: =B14/1000*Annahmen!$B$19 -> 0.00528 | C15: =C14/1000*Annahmen!$B$19 -> 0.00528 | D15: =D14/1000*Annahmen!$B$19 -> 0.00528 | E15: =E14/1000*Annahmen!$B$19 -> 0.03168
A16: Süßstoffkosten | B16: =B8*Annahmen!$B$20 -> 0 | C16: =C8*Annahmen!$B$20 -> 0.01 | D16: =D8*Annahmen!$B$20 -> 0 | E16: =E8*Annahmen!$B$20 -> 0
A17: Rezepturkosten gesamt (€ je Dose) | B17: =SUM(B13,B15,B16) -> 0.02838 | C17: =SUM(C13,C15,C16) -> 0.02914 | D17: =SUM(D13,D15,D16) -> 0.01914 | E17: =SUM(E13,E15,E16) -> 0.04554
A19: NÄHRWERTE UND POSITIONIERUNG
A20: Brennwert (kcal je 100 ml) | B20: =B7*4 -> 40 | C20: =C7*4 -> 24 | D20: =D7*4 -> 24 | E20: =E7*4 -> 24 | G20: Zucker liefert 4 kcal je Gramm. Süßstoffe liefern keine Kalorien.
A21: Brennwert je Dose (kcal) | B21: =B20*Annahmen!$B$5/100 -> 132 | C21: =C20*Annahmen!$B$5/100 -> 79.2 | D21: =D20*Annahmen!$B$5/100 -> 79.2 | E21: =E20*Annahmen!$B$5/100 -> 79.2 | G21: Vergleich: Coca-Cola hat ca. 139 kcal je 330-ml-Dose.
A22: Zucker je Dose (g) | B22: =B12 -> 33 | C22: =C12 -> 19.8 | D22: =D12 -> 19.8 | E22: =E12 -> 19.8

Sheet Stückkosten
A1: STÜCKKOSTEN JE DOSE
A3: Verwendete Kostenstufe (Dosen) | B3: =IFERROR(INDEX(Annahmen!$B$9:$D$9,MATCH(Annahmen!$B$4,Annahmen!$B$9:$D$9,1)),Annahmen!$B$9) -> 20000 | G3: Richtet sich nach der Chargengröße auf 'Annahmen'. Zwischenwerte nutzen die nächstniedrigere Stufe.
A5: Kostenposition | B5: A | C5: B | D5: C | E5: D
A6: Bezeichnung | B6: =Rezepturvarianten!B4 -> Vollzucker | C6: =Rezepturvarianten!C4 -> Fresca-Original (Hybrid) | D6: =Rezepturvarianten!D4 -> Nur Zucker, reduziert | E6: =Rezepturvarianten!E4 -> Nur Zucker + 6 % Saft
A7: Leerdose + Deckel | B7: =IFERROR(INDEX(Annahmen!$B$10:$D$10,MATCH(Annahmen!$B$4,Annahmen!$B$9:$D$9,1)),Annahmen!$B$10) -> 0.15 | C7: =IFERROR(INDEX(Annahmen!$B$10:$D$10,MATCH(Annahmen!$B$4,Annahmen!$B$9:$D$9,1)),Annahmen!$B$10) -> 0.15 | D7: =IFERROR(INDEX(Annahmen!$B$10:$D$10,MATCH(Annahmen!$B$4,Annahmen!$B$9:$D$9,1)),Annahmen!$B$10) -> 0.15 | E7: =IFERROR(INDEX(Annahmen!$B$10:$D$10,MATCH(Annahmen!$B$4,Annahmen!$B$9:$D$9,1)),Annahmen!$B$10) -> 0.15
A8: Sleeve (Druck + Aufbringen) | B8: =IFERROR(INDEX(Annahmen!$B$11:$D$11,MATCH(Annahmen!$B$4,Annahmen!$B$9:$D$9,1)),Annahmen!$B$11) -> 0.05 | C8: =IFERROR(INDEX(Annahmen!$B$11:$D$11,MATCH(Annahmen!$B$4,Annahmen!$B$9:$D$9,1)),Annahmen!$B$11) -> 0.05 | D8: =IFERROR(INDEX(Annahmen!$B$11:$D$11,MATCH(Annahmen!$B$4,Annahmen!$B$9:$D$9,1)),Annahmen!$B$11) -> 0.05 | E8: =IFERROR(INDEX(Annahmen!$B$11:$D$11,MATCH(Annahmen!$B$4,Annahmen!$B$9:$D$9,1)),Annahmen!$B$11) -> 0.05
A9: Abfüllung (Lohnkosten) | B9: =IFERROR(INDEX(Annahmen!$B$12:$D$12,MATCH(Annahmen!$B$4,Annahmen!$B$9:$D$9,1)),Annahmen!$B$12) -> 0.12 | C9: =IFERROR(INDEX(Annahmen!$B$12:$D$12,MATCH(Annahmen!$B$4,Annahmen!$B$9:$D$9,1)),Annahmen!$B$12) -> 0.12 | D9: =IFERROR(INDEX(Annahmen!$B$12:$D$12,MATCH(Annahmen!$B$4,Annahmen!$B$9:$D$9,1)),Annahmen!$B$12) -> 0.12 | E9: =IFERROR(INDEX(Annahmen!$B$12:$D$12,MATCH(Annahmen!$B$4,Annahmen!$B$9:$D$9,1)),Annahmen!$B$12) -> 0.12
A10: Sekundärverpackung | B10: =IFERROR(INDEX(Annahmen!$B$13:$D$13,MATCH(Annahmen!$B$4,Annahmen!$B$9:$D$9,1)),Annahmen!$B$13) -> 0.03 | C10: =IFERROR(INDEX(Annahmen!$B$13:$D$13,MATCH(Annahmen!$B$4,Annahmen!$B$9:$D$9,1)),Annahmen!$B$13) -> 0.03 | D10: =IFERROR(INDEX(Annahmen!$B$13:$D$13,MATCH(Annahmen!$B$4,Annahmen!$B$9:$D$9,1)),Annahmen!$B$13) -> 0.03 | E10: =IFERROR(INDEX(Annahmen!$B$13:$D$13,MATCH(Annahmen!$B$4,Annahmen!$B$9:$D$9,1)),Annahmen!$B$13) -> 0.03
A11: Basis-Rohstoffe | B11: =IFERROR(INDEX(Annahmen!$B$14:$D$14,MATCH(Annahmen!$B$4,Annahmen!$B$9:$D$9,1)),Annahmen!$B$14) -> 0.02 | C11: =IFERROR(INDEX(Annahmen!$B$14:$D$14,MATCH(Annahmen!$B$4,Annahmen!$B$9:$D$9,1)),Annahmen!$B$14) -> 0.02 | D11: =IFERROR(INDEX(Annahmen!$B$14:$D$14,MATCH(Annahmen!$B$4,Annahmen!$B$9:$D$9,1)),Annahmen!$B$14) -> 0.02 | E11: =IFERROR(INDEX(Annahmen!$B$14:$D$14,MATCH(Annahmen!$B$4,Annahmen!$B$9:$D$9,1)),Annahmen!$B$14) -> 0.02
A12: Aroma / Konzentrat | B12: =IFERROR(INDEX(Annahmen!$B$15:$D$15,MATCH(Annahmen!$B$4,Annahmen!$B$9:$D$9,1)),Annahmen!$B$15) -> 0.025 | C12: =IFERROR(INDEX(Annahmen!$B$15:$D$15,MATCH(Annahmen!$B$4,Annahmen!$B$9:$D$9,1)),Annahmen!$B$15) -> 0.025 | D12: =IFERROR(INDEX(Annahmen!$B$15:$D$15,MATCH(Annahmen!$B$4,Annahmen!$B$9:$D$9,1)),Annahmen!$B$15) -> 0.025 | E12: =IFERROR(INDEX(Annahmen!$B$15:$D$15,MATCH(Annahmen!$B$4,Annahmen!$B$9:$D$9,1)),Annahmen!$B$15) -> 0.025
A13: Zucker | B13: =Rezepturvarianten!B13 -> 0.0231 | C13: =Rezepturvarianten!C13 -> 0.01386 | D13: =Rezepturvarianten!D13 -> 0.01386 | E13: =Rezepturvarianten!E13 -> 0.01386
A14: Grapefruitsaft | B14: =Rezepturvarianten!B15 -> 0.00528 | C14: =Rezepturvarianten!C15 -> 0.00528 | D14: =Rezepturvarianten!D15 -> 0.00528 | E14: =Rezepturvarianten!E15 -> 0.03168
A15: Süßstoff | B15: =Rezepturvarianten!B16 -> 0 | C15: =Rezepturvarianten!C16 -> 0.01 | D15: =Rezepturvarianten!D16 -> 0 | E15: =Rezepturvarianten!E16 -> 0
A16: Herstellkosten ab Abfüller (Summe) | B16: =SUM(B7:B15) -> 0.42338 | C16: =SUM(C7:C15) -> 0.42414 | D16: =SUM(D7:D15) -> 0.41414 | E16: =SUM(E7:E15) -> 0.44054
A17: + EWP Pfand-Systembeitrag | B17: =Annahmen!$B$23 -> 0.02 | C17: =Annahmen!$B$23 -> 0.02 | D17: =Annahmen!$B$23 -> 0.02 | E17: =Annahmen!$B$23 -> 0.02
A18: + Fracht zum Lager | B18: =Annahmen!$B$24 -> 0.02 | C18: =Annahmen!$B$24 -> 0.02 | D18: =Annahmen!$B$24 -> 0.02 | E18: =Annahmen!$B$24 -> 0.02
A19: VOLLKOSTEN WARE (€ je Dose) | B19: =B16+B17+B18 -> 0.46338 | C19: =C16+C17+C18 -> 0.46414 | D19: =D16+D17+D18 -> 0.45414 | E19: =E16+E17+E18 -> 0.48054
A21: Nachrichtlich: kcal je Dose | B21: =Rezepturvarianten!B21 -> 132 | C21: =Rezepturvarianten!C21 -> 79.2 | D21: =Rezepturvarianten!D21 -> 79.2 | E21: =Rezepturvarianten!E21 -> 79.2
A22: Nachrichtlich: Zucker je Dose (g) | B22: =Rezepturvarianten!B22 -> 33 | C22: =Rezepturvarianten!C22 -> 19.8 | D22: =Rezepturvarianten!D22 -> 19.8 | E22: =Rezepturvarianten!E22 -> 19.8
A24: SKALENEFFEKT — Vollkosten Ware (€ je Dose) bei allen drei Chargengrößen
A25: Chargengröße | B25: A | C25: B | D25: C | E25: D
A26: =Annahmen!$B$9 -> 20000 | B26: =SUM(Annahmen!$B$10:$B$15)+Rezepturvarianten!B$17+Annahmen!$B$23+Annahmen!$B$24 -> 0.46338 | C26: =SUM(Annahmen!$B$10:$B$15)+Rezepturvarianten!C$17+Annahmen!$B$23+Annahmen!$B$24 -> 0.46414 | D26: =SUM(Annahmen!$B$10:$B$15)+Rezepturvarianten!D$17+Annahmen!$B$23+Annahmen!$B$24 -> 0.45414 | E26: =SUM(Annahmen!$B$10:$B$15)+Rezepturvarianten!E$17+Annahmen!$B$23+Annahmen!$B$24 -> 0.48054 | G26: Zeigt, wie stark die Menge auf die Stückkosten drückt — dein wichtigstes Argument in der Abfüller-Verhandlung.
A27: =Annahmen!$C$9 -> 50000 | B27: =SUM(Annahmen!$C$10:$C$15)+Rezepturvarianten!B$17+Annahmen!$B$23+Annahmen!$B$24 -> 0.39838 | C27: =SUM(Annahmen!$C$10:$C$15)+Rezepturvarianten!C$17+Annahmen!$B$23+Annahmen!$B$24 -> 0.39914 | D27: =SUM(Annahmen!$C$10:$C$15)+Rezepturvarianten!D$17+Annahmen!$B$23+Annahmen!$B$24 -> 0.38914 | E27: =SUM(Annahmen!$C$10:$C$15)+Rezepturvarianten!E$17+Annahmen!$B$23+Annahmen!$B$24 -> 0.41554
A28: =Annahmen!$D$9 -> 100000 | B28: =SUM(Annahmen!$D$10:$D$15)+Rezepturvarianten!B$17+Annahmen!$B$23+Annahmen!$B$24 -> 0.34438 | C28: =SUM(Annahmen!$D$10:$D$15)+Rezepturvarianten!C$17+Annahmen!$B$23+Annahmen!$B$24 -> 0.34514 | D28: =SUM(Annahmen!$D$10:$D$15)+Rezepturvarianten!D$17+Annahmen!$B$23+Annahmen!$B$24 -> 0.33514 | E28: =SUM(Annahmen!$D$10:$D$15)+Rezepturvarianten!E$17+Annahmen!$B$23+Annahmen!$B$24 -> 0.36154

Sheet Marge & Preiskette
A1: MARGE & PREISKETTE
A3: Gewählte Variante | B3: =Annahmen!$B$6 -> B
A4: Bezeichnung | B4: =IFERROR(INDEX(Rezepturvarianten!$B$4:$E$4,MATCH(Annahmen!$B$6,Stückkosten!$B$5:$E$5,0)),"?") -> Fresca-Original (Hybrid)
A5: Vollkosten Ware (€ je Dose) | B5: =IFERROR(INDEX(Stückkosten!$B$19:$E$19,MATCH(Annahmen!$B$6,Stückkosten!$B$5:$E$5,0)),0) -> 0.46414
A7: Kanal | B7: Abgabepreis netto | C7: Vollkosten Ware | D7: Rohertrag € / Dose | E7: Marge % | F7: Anteil | G7: Gewichteter Rohertrag
A8: =Annahmen!$A$44 -> Online-Direktverkauf | B8: =Annahmen!$B$44 -> 2.2 | C8: =$B$5 -> 0.46414 | D8: =B8-C8 -> 1.73586 | E8: =IFERROR(D8/B8,0) -> 0.78902727 | F8: =Annahmen!$C$44 -> 0.25 | G8: =D8*F8 -> 0.433965 | I8: Preise netto — ohne 20 % USt und ohne die 25 Cent Pfand (durchlaufender Posten).
A9: =Annahmen!$A$45 -> Gastronomie | B9: =Annahmen!$B$45 -> 1 | C9: =$B$5 -> 0.46414 | D9: =B9-C9 -> 0.53586 | E9: =IFERROR(D9/B9,0) -> 0.53586 | F9: =Annahmen!$C$45 -> 0.6 | G9: =D9*F9 -> 0.321516
A10: =Annahmen!$A$46 -> Feinkost / Getränkefachhandel | B10: =Annahmen!$B$46 -> 0.85 | C10: =$B$5 -> 0.46414 | D10: =B10-C10 -> 0.38586 | E10: =IFERROR(D10/B10,0) -> 0.45395294 | F10: =Annahmen!$C$46 -> 0.15 | G10: =D10*F10 -> 0.057879 | I10: Faustregel: Gastro und Direktverkauf verdienen das Geld, der LEH macht den Umsatz.
A11: =Annahmen!$A$47 -> LEH / Großhandel | B11: =Annahmen!$B$47 -> 0.72 | C11: =$B$5 -> 0.46414 | D11: =B11-C11 -> 0.25586 | E11: =IFERROR(D11/B11,0) -> 0.35536111 | F11: =Annahmen!$C$47 -> 0 | G11: =D11*F11 -> 0
A12: GEWICHTETER DURCHSCHNITT | B12: =SUMPRODUCT($B$8:$B$11,$F$8:$F$11) -> 1.2775 | C12: =$B$5 -> 0.46414 | D12: =SUM(G8:G11) -> 0.81336 | E12: =IFERROR(D12/B12,0) -> 0.63668102 | F12: =SUM(F8:F11) -> 1 | G12: =SUM(G8:G11) -> 0.81336
A14: Ø Abgabepreis je Dose | B14: =B12 -> 1.2775
A15: Ø Rohertrag je Dose | B15: =D12 -> 0.81336

Sheet Break-even
A1: BREAK-EVEN DER ERSTEN CHARGE
A3: ZU DECKENDE KOSTEN
A4: Einmalkosten gesamt | B4: =Annahmen!$B$33 -> 7450
A5: Fixkosten Jahr 1 | B5: =Annahmen!$B$40 -> 6000
A6: Summe | B6: =B4+B5 -> 13450
A8: BREAK-EVEN
A9: Ø Rohertrag je Dose | B9: ='Marge & Preiskette'!$B$15 -> 0.81336
A10: BREAK-EVEN (verkaufte Dosen) | B10: =IFERROR($B$6/$B$9,0) -> 16536.343
A11: Chargengröße | B11: =Annahmen!$B$4 -> 20000
A12: Break-even in % der Charge | B12: =IFERROR($B$10/$B$11,0) -> 0.82681715 | I12: =IF(B12>1,"ACHTUNG: Die erste Charge kann die Kosten rechnerisch nicht decken.","OK — der Break-even liegt innerhalb der ersten Charge.") -> OK — der Break-even liegt innerhalb der ersten Charge.
A14: SZENARIEN CHARGE 1 — die Ware wird voll produziert, aber nur teilweise verkauft
A15: Abverkauf | B15: Verkaufte Dosen | C15: Umsatz netto | D15: Wareneinsatz (volle Charge) | E15: Deckungsbeitrag | F15: Einmal- + Fixkosten | G15: ERGEBNIS
A16: 0.5 | B16: =$B$11*A16 -> 10000 | C16: =B16*'Marge & Preiskette'!$B$14 -> 12775 | D16: =-$B$11*'Marge & Preiskette'!$B$5 -> -9282.8 | E16: =C16+D16 -> 3492.2 | F16: =-$B$6 -> -13450 | G16: =E16+F16 -> -9957.8 | I16: Nicht verkaufte Dosen kosten trotzdem Geld — deshalb wird der Wareneinsatz immer für die volle Charge gerechnet. Das ist der ehrliche Blick.
A17: 0.75 | B17: =$B$11*A17 -> 15000 | C17: =B17*'Marge & Preiskette'!$B$14 -> 19162.5 | D17: =-$B$11*'Marge & Preiskette'!$B$5 -> -9282.8 | E17: =C17+D17 -> 9879.7 | F17: =-$B$6 -> -13450 | G17: =E17+F17 -> -3570.3
A18: 1 | B18: =$B$11*A18 -> 20000 | C18: =B18*'Marge & Preiskette'!$B$14 -> 25550 | D18: =-$B$11*'Marge & Preiskette'!$B$5 -> -9282.8 | E18: =C18+D18 -> 16267.2 | F18: =-$B$6 -> -13450 | G18: =E18+F18 -> 2817.2

Sheet Jahresszenarien
A1: JAHRESSZENARIEN — ab wann trägt es dich?
A3: Szenario | B3: Absatz Dosen / Jahr | C3: Vollkosten € / Dose | D3: Ø Abgabepreis | E3: Rohertrag gesamt | F3: Fixkosten p. a. | G3: ERGEBNIS | H3: je Monat
A4: Nebenbei | B4: 20000 | C4: =IFERROR(INDEX(Stückkosten!$B$26:$E$28,MATCH(B4,Stückkosten!$A$26:$A$28,1),MATCH(Annahmen!$B$6,Stückkosten!$B$25:$E$25,0)),0) -> 0.46414 | D4: ='Marge & Preiskette'!$B$14 -> 1.2775 | E4: =B4*(D4-C4) -> 16267.2 | F4: 4000 | G4: =E4-F4 -> 12267.2 | H4: =G4/12 -> 1022.2667 | J4: Fixkosten sind Eingaben — schätze sie ehrlich. Ab 'Hauptberuf' gehört dein eigenes Gehalt hinein, sonst rechnest du dich reich.
A5: Halbtags | B5: 80000 | C5: =IFERROR(INDEX(Stückkosten!$B$26:$E$28,MATCH(B5,Stückkosten!$A$26:$A$28,1),MATCH(Annahmen!$B$6,Stückkosten!$B$25:$E$25,0)),0) -> 0.39914 | D5: ='Marge & Preiskette'!$B$14 -> 1.2775 | E5: =B5*(D5-C5) -> 70268.8 | F5: 25000 | G5: =E5-F5 -> 45268.8 | H5: =G5/12 -> 3772.4
A6: Hauptberuf | B6: 200000 | C6: =IFERROR(INDEX(Stückkosten!$B$26:$E$28,MATCH(B6,Stückkosten!$A$26:$A$28,1),MATCH(Annahmen!$B$6,Stückkosten!$B$25:$E$25,0)),0) -> 0.34514 | D6: ='Marge & Preiskette'!$B$14 -> 1.2775 | E6: =B6*(D6-C6) -> 186472 | F6: 70000 | G6: =E6-F6 -> 116472 | H6: =G6/12 -> 9706 | J6: Ab 100.000 Dosen bleibt die Kostenstufe rechnerisch stehen. Bei 500.000 wären die echten Stückkosten niedriger — hier bewusst konservativ.
A7: Ernsthaft | B7: 500000 | C7: =IFERROR(INDEX(Stückkosten!$B$26:$E$28,MATCH(B7,Stückkosten!$A$26:$A$28,1),MATCH(Annahmen!$B$6,Stückkosten!$B$25:$E$25,0)),0) -> 0.34514 | D7: ='Marge & Preiskette'!$B$14 -> 1.2775 | E7: =B7*(D7-C7) -> 466180 | F7: 180000 | G7: =E7-F7 -> 286180 | H7: =G7/12 -> 23848.333
A10: WAS DAS HAUPTBERUF-SZENARIO PRAKTISCH BEDEUTET
A11: Dosen je Tag | B11: =B6/365 -> 547.94521
A12: Gastro-Betriebe nötig | B12: 100
A13: Dosen je Betrieb und Tag | B13: =IFERROR($B$11/$B$12,0) -> 5.4794521 | J13: Das ist die eigentliche Arbeit: so viele Betriebe gewinnen UND halten.

Sheet Verkostung
A1: BLINDVERKOSTUNG — AUSWERTUNG
A3: SO GEHT ES
A4: 1. Muster in identische, undurchsichtige Becher füllen und NUR mit dem Zahlencode beschriften.
A5: 2. Reihenfolge bei jedem Teilnehmer wechseln. Wasser und etwas Brot zum Neutralisieren dazustellen.
A6: 3. Erst den Papierbogen ausfüllen lassen (PDF im Projektordner), danach die Zahlen hier eintragen.
A7: 4. Die Legende unten darf niemand sehen, bevor alle Bögen ausgefüllt sind.
A9: BLINDCODES — Legende (geheim halten!)
A10: Code | B10: Muster
A11: 471 | B11: Referenz — Fresca Original (Import)
A12: 628 | B12: Variante A — Vollzucker
A13: 359 | B13: Variante B — Fresca-Original (Hybrid, mit Süßstoff)
A14: 815 | B14: Variante C — Nur Zucker, reduziert
A16: AUSWERTUNG — rechnet automatisch
A17: Kennzahl | B17: =A11 -> 471 | C17: =A12 -> 628 | D17: =A13 -> 359 | E17: =A14 -> 815
A18: Ø Gesamteindruck (1–10) | B18: =IFERROR(AVERAGE(B$30:B$77),0) -> 0 | C18: =IFERROR(AVERAGE(C$30:C$77),0) -> 0 | D18: =IFERROR(AVERAGE(D$30:D$77),0) -> 0 | E18: =IFERROR(AVERAGE(E$30:E$77),0) -> 0
A19: Ø Süßeempfinden (1 = zu wenig … 9 = zu süß) | B19: =IFERROR(AVERAGE(F$30:F$77),0) -> 0 | C19: =IFERROR(AVERAGE(G$30:G$77),0) -> 0 | D19: =IFERROR(AVERAGE(H$30:H$77),0) -> 0 | E19: =IFERROR(AVERAGE(I$30:I$77),0) -> 0
A20: Anzahl "würde ich kaufen" | B20: =COUNTIF($J$30:$J$77,B$17) -> 0 | C20: =COUNTIF($J$30:$J$77,C$17) -> 0 | D20: =COUNTIF($J$30:$J$77,D$17) -> 0 | E20: =COUNTIF($J$30:$J$77,E$17) -> 0
A21: Anteil Kaufpräferenz | B21: =IFERROR(B20/$B$24,0) -> 0 | C21: =IFERROR(C20/$B$24,0) -> 0 | D21: =IFERROR(D20/$B$24,0) -> 0 | E21: =IFERROR(E20/$B$24,0) -> 0
A22: Differenz zur Referenz (Gesamteindruck) | B22: =B18-$B$18 -> 0 | C22: =C18-$B$18 -> 0 | D22: =D18-$B$18 -> 0 | E22: =E18-$B$18 -> 0
A24: Teilnehmer erfasst | B24: =COUNT($B$30:$B$77) -> 0
A25: Bestes Muster (Ø Gesamteindruck) | B25: =IF($B$24=0,"— noch keine Daten erfasst —",IFERROR(INDEX($B$11:$B$14,MATCH(INDEX($B$17:$E$17,MATCH(MAX($B$18:$E$18),$B$18:$E$18,0)),$A$11:$A$14,0)),"—")) -> — noch keine Daten erfasst —
A26: ENTSCHEIDUNGSREGEL | B26: Schlägt keine eigene Variante die Referenz um mindestens 0,5 Punkte, ist die Rezeptur noch nicht fertig.
A27: DATENEINGABE — eine Zeile je Teilnehmer
A28: Teilnehmer | B28: Gesamt Code 1 | C28: Gesamt Code 2 | D28: Gesamt Code 3 | E28: Gesamt Code 4 | F28: Süße Code 1 | G28: Süße Code 2 | H28: Süße Code 3 | I28: Süße Code 4 | J28: Kauf-Code | K28: Notiz
A29: BEISPIEL | B29: 7 | C29: 5 | D29: 8 | E29: 6 | F29: 5 | G29: 8 | H29: 5 | I29: 3 | J29: 359 | K29: B am rundesten, C zu trocken | L29: ◄ Beispielzeile. Sie wird NICHT mitgerechnet — echte Daten ab Zeile 30.
A30: 1
A31: 2
A32: 3
A33: 4
A34: 5
A35: 6
A36: 7
A37: 8
A38: 9
A39: 10
A40: 11
A41: 12
... A77: 48
